Конструкция try..catch состоит из двух основных блоков: try, и затем catch:

try {

  // код...

} catch (err) {

  // обработка ошибки

}


Для всех встроенных ошибок этот объект имеет два основных свойства:

name
    Имя ошибки. Например, для неопределённой переменной это "ReferenceError".
message
    Текстовое сообщение о деталях ошибки.

В большинстве окружений доступны и другие, нестандартные свойства. Одно из самых широко используемых и поддерживаемых – это:

stack
    Текущий стек вызова: строка, содержащая информацию о последовательности вложенных вызовов, которые привели к ошибке. Используется в целях отладки.


    Оператор throw генерирует ошибку.

    Синтаксис:

    throw <объект ошибки>


В JavaScript есть множество встроенных конструкторов для стандартных ошибок: Error, SyntaxError, ReferenceError, TypeError и другие. Можно использовать и их для создания объектов ошибки.

Их синтаксис:

let error = new Error(message);
// или
let error = new SyntaxError(message);
let error = new ReferenceError(message);
// ...


Конструкция try..catch может содержать ещё одну секцию: finally.

Если секция есть, то она выполняется в любом случае:

    после try, если не было ошибок,
    после catch, если ошибки были.



